package com.example.ktlearntest.coroutines

import kotlinx.coroutines.*

/**
 * 如果在 concurrentSum 函数内部发生了错误，并且它抛出了一个异常， 所有在作用域中启动的协程都会被取消。
 */
fun main() = runBlocking<Unit> {
    try {
        failedConcurrentSum()
    } catch(e: ArithmeticException) {
        println("Computation failed with ArithmeticException")
    }
}

suspend fun failedConcurrentSum(): Int = coroutineScope {
    val one = async<Int> {
        try {
            delay(Long.MAX_VALUE) // 模拟一个长时间的运算
            42
        } finally {
            println("First child was cancelled")
        }
    }
    val two = async<Int> {
        println("Second child throws an exception")
        throw ArithmeticException()
    }
    one.await() + two.await()
}

//Second child throws an exception
//First child was cancelled
//Computation failed with ArithmeticException